<?xml version="0.0" ?>
<robot name="">

	<material name="Grey">
		<color rgba="0.2 0.2 0.2 1.0"/>
	</material>
	<material name="Orange">
		<color rgba="1.0 0.423529411765 0.0392156862745 1.0"/>
	</material>
	<material name="Blue">
		<color rgba="0.5 0.7 1.0 1.0"/>      
	</material>


	<link name="lbr_iiwa_link_0">
		<inertial>
			<origin rpy="0.00000 -0.00000 0.00000" xyz="-0.10000 0.00000 0.07000"/>
			<mass value="0.00000"/>
			<inertia ixx="0.00000" ixy="0" ixz="0" iyy="0.00000" iyz="0" izz="0.00000"/>
		</inertial>
		<visual>
			<origin rpy="0.00000 -0.00000 0.00000" xyz="0.00000 0.00000 0.00000"/>
			<geometry>
				<mesh filename="meshes_kuka/link_0.obj" scale="1.00000 1.00000 1.00000"/>
			</geometry>
			<material name="Grey"/>
		</visual>
		<collision>
			<origin rpy="0.00000 -0.00000 0.00000" xyz="0.00000 0.00000 0.00000"/>
			<geometry>
				<mesh filename="meshes_kuka/link_0.stl" scale="1.00000 1.00000 1.00000"/>
			</geometry>
		</collision>
	</link>
	<link name="lbr_iiwa_link_1">
		<inertial>
			<origin rpy="0.00000 -0.00000 0.00000" xyz="0.00000 -0.03000 0.12000"/>
			<mass value="4.00000"/>
			<inertia ixx="0.04509" ixy="0" ixz="0" iyy="0.04124" iyz="0" izz="0.02474"/>
		</inertial>
		<visual>
			<origin rpy="0.00000 -0.00000 0.00000" xyz="0.00000 0.00000 0.00000"/>
			<geometry>
				<mesh filename="meshes_kuka/link_1.obj" scale="1.00000 1.00000 1.00000"/>
			</geometry>
			<material name="Blue"/>
		</visual>
		<collision>
			<origin rpy="0.00000 -0.00000 0.00000" xyz="0.00000 0.00000 0.00000"/>
			<geometry>
				<mesh filename="meshes_kuka/link_1.stl" scale="1.00000 1.00000 1.00000"/>
			</geometry>
		</collision>
	</link>
	<link name="lbr_iiwa_link_2">
		<inertial>
			<origin rpy="0.00000 -0.00000 0.00000" xyz="0.00030 0.05900 0.04200"/>
			<mass value="4.00000"/>
			<inertia ixx="0.04343" ixy="0" ixz="0" iyy="0.02460" iyz="0" izz="0.03965"/>
		</inertial>
		<visual>
			<origin rpy="0.00000 -0.00000 0.00000" xyz="0.00000 0.00000 0.00000"/>
			<geometry>
				<mesh filename="meshes_kuka/link_2.obj" scale="1.00000 1.00000 1.00000"/>
			</geometry>
			<material name="Blue"/>
		</visual>
		<collision>
			<origin rpy="0.00000 -0.00000 0.00000" xyz="0.00000 0.00000 0.00000"/>
			<geometry>
				<mesh filename="meshes_kuka/link_2.stl" scale="1.00000 1.00000 1.00000"/>
			</geometry>
		</collision>
	</link>
	<link name="lbr_iiwa_link_3">
		<inertial>
			<origin rpy="0.00000 -0.00000 0.00000" xyz="0.00000 0.03000 0.13000"/>
			<mass value="3.00000"/>
			<inertia ixx="0.03130" ixy="0" ixz="0" iyy="0.02744" iyz="0" izz="0.01394"/>
		</inertial>
		<visual>
			<origin rpy="0.00000 -0.00000 0.00000" xyz="0.00000 0.00000 0.00000"/>
			<geometry>
				<mesh filename="meshes_kuka/link_3.obj" scale="1.00000 1.00000 1.00000"/>
			</geometry>
			<material name="Orange"/>
		</visual>
		<collision>
			<origin rpy="0.00000 -0.00000 0.00000" xyz="0.00000 0.00000 0.00000"/>
			<geometry>
				<mesh filename="meshes_kuka/link_3.stl" scale="1.00000 1.00000 1.00000"/>
			</geometry>
		</collision>
	</link>
	<link name="lbr_iiwa_link_4">
		<inertial>
			<origin rpy="0.00000 -0.00000 0.00000" xyz="0.00000 0.06700 0.03400"/>
			<mass value="2.70000"/>
			<inertia ixx="0.02302" ixy="0" ixz="0" iyy="0.01255" iyz="0" izz="0.01957"/>
		</inertial>
		<visual>
			<origin rpy="0.00000 -0.00000 0.00000" xyz="0.00000 0.00000 0.00000"/>
			<geometry>
				<mesh filename="meshes_kuka/link_4.obj" scale="1.00000 1.00000 1.00000"/>
			</geometry>
     	 	<material name="Blue"/>
		</visual>
		<collision>
			<origin rpy="0.00000 -0.00000 0.00000" xyz="0.00000 0.00000 0.00000"/>
			<geometry>
				<mesh filename="meshes_kuka/link_4.stl" scale="1.00000 1.00000 1.00000"/>
			</geometry>
		</collision>
	</link>
	<link name="lbr_iiwa_link_5">
		<inertial>
			<origin rpy="0.00000 -0.00000 0.00000" xyz="0.00010 0.02100 0.07600"/>
			<mass value="1.70000"/>
			<inertia ixx="0.01559" ixy="0" ixz="0" iyy="0.01421" iyz="0" izz="0.00710"/>
		</inertial>
		<visual>
			<origin rpy="0.00000 -0.00000 0.00000" xyz="0.00000 0.00000 0.00000"/>
			<geometry>
				<mesh filename="meshes_kuka/link_5.obj" scale="1.00000 1.00000 1.00000"/>
			</geometry>
			<material name="Blue"/>
		</visual>
		<collision>
			<origin rpy="0.00000 -0.00000 0.00000" xyz="0.00000 0.00000 0.00000"/>
			<geometry>
				<mesh filename="meshes_kuka/link_5.stl" scale="1.00000 1.00000 1.00000"/>
			</geometry>
		</collision>
	</link>
	<link name="lbr_iiwa_link_6">
		<inertial>
			<origin rpy="0.00000 -0.00000 0.00000" xyz="0.00000 0.00060 0.00040"/>
			<mass value="1.80000"/>
			<inertia ixx="0.00761" ixy="0" ixz="0" iyy="0.00597" iyz="0" izz="0.00738"/>
		</inertial>
		<visual>
			<origin rpy="0.00000 -0.00000 0.00000" xyz="0.00000 0.00000 0.00000"/>
			<geometry>
				<mesh filename="meshes_kuka/link_6.obj" scale="1.00000 1.00000 1.00000"/>
			</geometry>
			<material name="Orange"/>
		</visual>
		<collision>
			<origin rpy="0.00000 -0.00000 0.00000" xyz="0.00000 0.00000 0.00000"/>
			<geometry>
				<mesh filename="meshes_kuka/link_6.stl" scale="1.00000 1.00000 1.00000"/>
			</geometry>
		</collision>
	</link>
	<link name="lbr_iiwa_link_7">
		<inertial>
			<origin rpy="0.00000 -0.00000 0.00000" xyz="0.00000 0.00000 0.02000"/>
			<mass value="0.30000"/>
			<inertia ixx="0.00039" ixy="0" ixz="0" iyy="0.00040" iyz="0" izz="0.00060"/>
		</inertial>
		<visual>
			<origin rpy="0.00000 -0.00000 0.00000" xyz="0.00000 0.00000 0.00000"/>
			<geometry>
				<mesh filename="meshes_kuka/link_7.obj" scale="1.00000 1.00000 1.00000"/>
			</geometry>
			<material name="Grey"/>
		</visual>
		<collision>
			<origin rpy="0.00000 -0.00000 0.00000" xyz="0.00000 0.00000 0.00000"/>
			<geometry>
				<mesh filename="meshes_kuka/link_7.stl" scale="1.00000 1.00000 1.00000"/>
			</geometry>
		</collision>
	</link>
	<link name="$palm_link">
		<inertial>
			<origin rpy="0.00000 -0.00000 0.00000" xyz="0.00000 0.00000 0.03860"/>
			<mass value="1.02880"/>
			<inertia ixx="0.00203" ixy="0" ixz="0" iyy="0.00182" iyz="0" izz="0.00267"/>
		</inertial>
		<visual>
			<origin rpy="0.00000 -0.00000 0.00000" xyz="0.00000 0.00000 0.00000"/>
			<geometry>
				<mesh filename="meshes_SDH/palm.stl" scale="1.00000 1.00000 1.00000"/>
			</geometry>
			<material name="Schunk/DarkGrey">
		        <color rgba="1 0.84 0 1.0"/>
		    </material>
		</visual>
		<collision>
			<origin rpy="0.00000 -0.00000 0.00000" xyz="0.00000 0.00000 0.00000"/>
			<geometry>
				<mesh filename="meshes_SDH/palm_collision.stl" scale="1.00000 1.00000 1.00000"/>
			</geometry>
		</collision>
	</link>
	<link name="$finger_11_link">
		<inertial>
			<origin rpy="0.00000 -0.00000 0.00000" xyz="0.00000 0.00221 0.01215"/>
			<mass value="0.04700"/>
			<inertia ixx="0.00002" ixy="0" ixz="0" iyy="0.00002" iyz="0" izz="0.00002"/>
		</inertial>
		<visual>
			<origin rpy="0.00000 -0.00000 0.00000" xyz="0.00000 0.00000 0.00000"/>
			<geometry>
				<mesh filename="meshes_SDH/knuckle.stl" scale="1.00000 1.00000 1.00000"/>
			</geometry>
			<material name="Schunk/DarkGrey">
				<color rgba="1 0.84 0 1.0"/>
			</material>
		</visual>
		<collision>
			<origin rpy="0.00000 -0.00000 0.00000" xyz="0.00000 0.00000 0.00000"/>
			<geometry>
				<mesh filename="meshes_SDH/knuckle_collision.stl" scale="1.00000 1.00000 1.00000"/>
			</geometry>
		</collision>
	</link>
	<link name="$finger_12_link">
		<inertial>
			<origin rpy="0.00000 -0.00000 0.00000" xyz="0.00075 -0.00004 0.04302"/>
			<mass value="0.16700"/>
			<inertia ixx="0.00022" ixy="0" ixz="0" iyy="0.00022" iyz="0" izz="0.00003"/>
		</inertial>
		<visual>
			<origin rpy="0.00000 -0.00000 0.00000" xyz="0.00000 0.00000 0.00000"/>
			<geometry>
				<mesh filename="meshes_SDH/finger.stl" scale="1.00000 1.00000 1.00000"/>
			</geometry>
			<material name="Schunk/LightGrey">
				<color rgba="1 0.84 0 1.0"/>
			</material>
		</visual>
		<collision>
			<origin rpy="0.00000 -0.00000 0.00000" xyz="0.00000 0.00000 0.00000"/>
			<geometry>
				<mesh filename="meshes_SDH/finger.stl" scale="1.00000 1.00000 1.00000"/>
			</geometry>
		</collision>
	</link>
	<link name="$finger_13_link">
		<inertial>
			<origin rpy="0.00000 -0.00000 0.00000" xyz="0.00075 -0.00004 0.04302"/>
			<mass value="0.09290"/>
			<inertia ixx="0.00007" ixy="0" ixz="0" iyy="0.00007" iyz="0" izz="0.00002"/>
		</inertial>
		<visual>
			<origin rpy="0.00000 -0.00000 0.00000" xyz="0.00000 0.00000 0.00000"/>
			<geometry>
				<mesh filename="meshes_SDH/finger_tip.stl" scale="1.00000 1.00000 1.00000"/>
			</geometry>
			<material name="Schunk/LightGrey">
				<color rgba="1 0.84 0 1.0"/>
			</material>
		</visual>
		<collision>
			<origin rpy="0.00000 -0.00000 0.00000" xyz="0.00000 0.00000 0.00000"/>
			<geometry>
				<mesh filename="meshes_SDH/finger_tip.stl" scale="1.00000 1.00000 1.00000"/>
			</geometry>
		</collision>
	</link>
	<link name="$finger_21_link">
		<inertial>
			<origin rpy="0.00000 -0.00000 0.00000" xyz="0.00000 0.00221 0.01215"/>
			<mass value="0.04700"/>
			<inertia ixx="0.00002" ixy="0" ixz="0" iyy="0.00002" iyz="0" izz="0.00002"/>
		</inertial>
		<visual>
			<origin rpy="0.00000 -0.00000 0.00000" xyz="0.00000 0.00000 0.00000"/>
			<geometry>
				<mesh filename="meshes_SDH/knuckle.stl" scale="1.00000 1.00000 1.00000"/>
			</geometry>
      		<material name="Schunk/DarkGrey">
        		<color rgba="1 0.84 0 1.0"/>
      		</material>
		</visual>
		<collision>
			<origin rpy="0.00000 -0.00000 0.00000" xyz="0.00000 0.00000 0.00000"/>
			<geometry>
				<mesh filename="meshes_SDH/knuckle_collision.stl" scale="1.00000 1.00000 1.00000"/>
			</geometry>
		</collision>
	</link>
	<link name="$finger_22_link">
		<inertial>
			<origin rpy="0.00000 -0.00000 0.00000" xyz="0.00075 -0.00004 0.04302"/>
			<mass value="0.16700"/>
			<inertia ixx="0.00022" ixy="0" ixz="0" iyy="0.00022" iyz="0" izz="0.00003"/>
		</inertial>
		<visual>
			<origin rpy="0.00000 -0.00000 0.00000" xyz="0.00000 0.00000 0.00000"/>
			<geometry>
				<mesh filename="meshes_SDH/finger.stl" scale="1.00000 1.00000 1.00000"/>
			</geometry>
      		<material name="Schunk/LightGrey">
       			 <color rgba="1 0.84 0 1.0"/>
      		</material>
		</visual>
		<collision>
			<origin rpy="0.00000 -0.00000 0.00000" xyz="0.00000 0.00000 0.00000"/>
			<geometry>
				<mesh filename="meshes_SDH/finger.stl" scale="1.00000 1.00000 1.00000"/>
			</geometry>
		</collision>
	</link>
	<link name="$finger_23_link">
		<inertial>
			<origin rpy="0.00000 -0.00000 0.00000" xyz="0.00075 -0.00004 0.04302"/>
			<mass value="0.09290"/>
			<inertia ixx="0.00007" ixy="0" ixz="0" iyy="0.00007" iyz="0" izz="0.00002"/>
		</inertial>
		<visual>
			<origin rpy="0.00000 -0.00000 0.00000" xyz="0.00000 0.00000 0.00000"/>
			<geometry>
				<mesh filename="meshes_SDH/finger_tip.stl" scale="1.00000 1.00000 1.00000"/>
			</geometry>
     		<material name="Schunk/LightGrey">
        		<color rgba="1 0.84 0 1.0"/>
      		</material>
		</visual>
		<collision>
			<origin rpy="0.00000 -0.00000 0.00000" xyz="0.00000 0.00000 0.00000"/>
			<geometry>
				<mesh filename="meshes_SDH/finger_tip.stl" scale="1.00000 1.00000 1.00000"/>
			</geometry>
		</collision>
	</link>
	<link name="$thumb_1_link">
		<inertial>
			<origin rpy="0.00000 -0.00000 0.00000" xyz="0.00000 0.00221 0.01215"/>
			<mass value="0.04700"/>
			<inertia ixx="0.00002" ixy="0" ixz="0" iyy="0.00002" iyz="0" izz="0.00002"/>
		</inertial>
		<visual>
			<origin rpy="0.00000 -0.00000 0.00000" xyz="0.00000 0.00000 0.00000"/>
			<geometry>
				<mesh filename="meshes_SDH/knuckle.stl" scale="1.00000 1.00000 1.00000"/>
			</geometry>
			<material name="Schunk/DarkGrey">
				<color rgba="1 0.84 0 1.0"/>
			</material>
		</visual>
		<collision>
			<origin rpy="0.00000 -0.00000 0.00000" xyz="0.00000 0.00000 0.00000"/>
			<geometry>
				<mesh filename="meshes_SDH/knuckle_collision.stl" scale="1.00000 1.00000 1.00000"/>
			</geometry>
		</collision>
	</link>
	<link name="$thumb_2_link">
		<inertial>
			<origin rpy="0.00000 -0.00000 0.00000" xyz="0.00075 -0.00004 0.04302"/>
			<mass value="0.16700"/>
			<inertia ixx="0.00022" ixy="0" ixz="0" iyy="0.00022" iyz="0" izz="0.00003"/>
		</inertial>
		<visual>
			<origin rpy="0.00000 -0.00000 0.00000" xyz="0.00000 0.00000 0.00000"/>
			<geometry>
				<mesh filename="meshes_SDH/finger.stl" scale="1.00000 1.00000 1.00000"/>
			</geometry>
			<material name="Schunk/LightGrey">
				<color rgba="1 0.84 0 1.0"/>
			</material>
		</visual>
		<collision>
			<origin rpy="0.00000 -0.00000 0.00000" xyz="0.00000 0.00000 0.00000"/>
			<geometry>
				<mesh filename="meshes_SDH/finger.stl" scale="1.00000 1.00000 1.00000"/>
			</geometry>
		</collision>
	</link>
	<link name="$thumb_3_link">
		<inertial>
			<origin rpy="0.00000 -0.00000 0.00000" xyz="0.00075 -0.00004 0.04302"/>
			<mass value="0.09290"/>
			<inertia ixx="0.00007" ixy="0" ixz="0" iyy="0.00007" iyz="0" izz="0.00002"/>
		</inertial>
		<visual>
			<origin rpy="0.00000 -0.00000 0.00000" xyz="0.00000 0.00000 0.00000"/>
			<geometry>
				<mesh filename="meshes_SDH/finger_tip.stl" scale="1.00000 1.00000 1.00000"/>
			</geometry>
     		<material name="Schunk/LightGrey">
       			 <color rgba="1 0.84 0 1.0"/>
      		</material>
		</visual>
		<collision>
			<origin rpy="0.00000 -0.00000 0.00000" xyz="0.00000 0.00000 0.00000"/>
			<geometry>
				<mesh filename="meshes_SDH/finger_tip.stl" scale="1.00000 1.00000 1.00000"/>
			</geometry>
		</collision>
	</link>


	<joint name="lbr_iiwa_joint_1" type="revolute">
		<limit effort="300" lower="-2.96705972839" upper="2.96705972839" velocity="10"/>
		<parent link="lbr_iiwa_link_0"/>
		<child link="lbr_iiwa_link_1"/>
		<origin rpy="0.00000 -0.00000 0.00000" xyz="0.00000 0.00000 0.15750"/>
		<axis xyz="0.00000 0.00000 1.00000"/>
	    <dynamics damping="0.5"/>
	</joint>
	<joint name="lbr_iiwa_joint_2" type="revolute">
		<parent link="lbr_iiwa_link_1"/>
		<child link="lbr_iiwa_link_2"/>
		<dynamics damping="1.0" friction="0.0001"/>
		<origin rpy="1.57080 -0.00000 -3.14159" xyz="0.00000 0.00000 0.20250"/>
		<axis xyz="0.00000 0.00000 1.00000"/>
		<limit effort="300" lower="-2.09439510239" upper="2.09439510239" velocity="10"/>
    	<dynamics damping="0.5"/>
	</joint>
	<joint name="lbr_iiwa_joint_3" type="revolute">
		<parent link="lbr_iiwa_link_2"/>
		<child link="lbr_iiwa_link_3"/>
		<dynamics damping="1.0" friction="0.0001"/>
		<origin rpy="1.57080 -0.00000 -3.14159" xyz="0.00000 0.20450 0.00000"/>
		<axis xyz="0.00000 0.00000 1.00000"/>
		<limit effort="300" lower="-2.96705972839" upper="2.96705972839" velocity="10"/>
    	<dynamics damping="0.5"/>
	</joint>
	<joint name="lbr_iiwa_joint_4" type="revolute">
		<parent link="lbr_iiwa_link_3"/>
		<child link="lbr_iiwa_link_4"/>
		<dynamics damping="1.0" friction="0.0001"/>
		<origin rpy="1.57080 -0.00000 0.00000" xyz="0.00000 0.00000 0.21550"/>
		<axis xyz="0.00000 0.00000 1.00000"/>
		<limit effort="300" lower="-2.09439510239" upper="2.09439510239" velocity="10"/>
    	<dynamics damping="0.5"/>
	</joint>
	<joint name="lbr_iiwa_joint_5" type="revolute">
		<parent link="lbr_iiwa_link_4"/>
		<child link="lbr_iiwa_link_5"/>
		<dynamics damping="1.0" friction="0.0001"/>
		<origin rpy="1.57080 -0.00000 3.14159" xyz="0.00000 0.18450 0.00000"/>
		<axis xyz="0.00000 0.00000 1.00000"/>
		<limit effort="300" lower="-2.96705972839" upper="2.96705972839" velocity="10"/>
    	<dynamics damping="0.5"/>
	</joint>
	<joint name="lbr_iiwa_joint_6" type="revolute">
		<parent link="lbr_iiwa_link_5"/>
		<child link="lbr_iiwa_link_6"/>
		<dynamics damping="1.0" friction="0.0001"/>
		<origin rpy="1.57080 -0.00000 0.00000" xyz="0.00000 0.00000 0.21550"/>
		<axis xyz="0.00000 0.00000 1.00000"/>
		<limit effort="300" lower="-2.09439510239" upper="2.09439510239" velocity="10"/>
    	<dynamics damping="0.5"/>
	</joint>
	<joint name="lbr_iiwa_joint_7" type="revolute">
		<parent link="lbr_iiwa_link_6"/>
		<child link="lbr_iiwa_link_7"/>
		<dynamics damping="1.0" friction="0.0001"/>
		<origin rpy="1.57080 -0.00000 3.14159" xyz="0.00000 0.08100 0.00000"/>
		<axis xyz="0.00000 0.00000 1.00000"/>
		<limit effort="300" lower="-3.05432619099" upper="3.05432619099" velocity="10"/>
    	<dynamics damping="0.5"/>
	</joint>
	<joint name="joint_dummy1" type="fixed">
		<parent link="lbr_iiwa_link_7"/>
		<child link="$palm_link"/>
		<dynamics damping="1.0" friction="0.0001"/>
		<origin rpy="0.00000 0.00000 0.00000" xyz="0.00000 0.00000 0.03000"/>
		<axis xyz="0.00000 0.00000 1.00000"/>
	</joint>
	<joint name="$knuckle_joint" type="revolute">
		<parent link="$palm_link"/>
		<child link="$finger_11_link"/>
		<dynamics damping="1.0" friction="0.0001"/>
		<origin rpy="0.00000 -0.00000 3.14159" xyz="0.01905 0.03300 0.07450"/>
		<axis xyz="0.00000 0.00000 1.00000"/>
		<limit effort="100" lower="0" upper="1.570796327" velocity="5"/>
	</joint>
	<joint name="$finger_12_joint" type="revolute">
		<parent link="$finger_11_link"/>
		<child link="$finger_12_link"/>
		<dynamics damping="1.0" friction="0.0001"/>
		<origin rpy="0.00000 -0.00000 0.00000" xyz="0.00000 0.00000 0.01650"/>
		<axis xyz="0.00000 1.00000 0.00000"/>
    	<limit effort="100" lower="-1.570796327" upper="1.570796327" velocity="5"/>
	</joint>
	<joint name="$finger_13_joint" type="revolute">
		<parent link="$finger_12_link"/>
		<child link="$finger_13_link"/>
		<dynamics damping="1.0" friction="0.0001"/>
		<origin rpy="0.00000 -0.00000 0.00000" xyz="0.00000 0.00000 0.08650"/>
		<axis xyz="0.00000 1.00000 0.00000"/>
		<limit effort="100" lower="-1.570796327" upper="1.570796327" velocity="5"/>
	</joint>
	<joint name="$finger_21_joint" type="revolute">
		<parent link="$palm_link"/>
		<child link="$finger_21_link"/>
		<dynamics damping="1.0" friction="0.0001"/>
		<origin rpy="0.00000 -0.00000 3.14159" xyz="0.01905 -0.03300 0.07450"/>
		<axis xyz="0.00000 0.00000 -1.00000"/>
		<limit effort="100" lower="0" upper="1.570796327" velocity="5"/>
	</joint>
	<joint name="$finger_22_joint" type="revolute">
		<parent link="$finger_21_link"/>
		<child link="$finger_22_link"/>
		<dynamics damping="1.0" friction="0.0001"/>
		<origin rpy="0.00000 -0.00000 0.00000" xyz="0.00000 0.00000 0.01650"/>
		<axis xyz="0.00000 1.00000 0.00000"/>
		<limit effort="100" lower="-1.570796327" upper="1.570796327" velocity="5"/>
	</joint>
	<joint name="$finger_23_joint" type="revolute">
		<parent link="$finger_22_link"/>
		<child link="$finger_23_link"/>
		<dynamics damping="1.0" friction="0.0001"/>
		<origin rpy="0.00000 -0.00000 0.00000" xyz="0.00000 0.00000 0.08650"/>
		<axis xyz="0.00000 1.00000 0.00000"/>
		<limit effort="100" lower="-1.570796327" upper="1.570796327" velocity="5"/>
	</joint>
	<joint name="$thumb_1_joint" type="fixed">
		<parent link="$palm_link"/>
		<child link="$thumb_1_link"/>
		<dynamics damping="1.0" friction="0.0001"/>
		<origin rpy="0.00000 -0.00000 0.00000" xyz="-0.03811 0.00000 0.07450"/>
		<axis xyz="0.00000 0.00000 0.00000"/>
	</joint>
	<joint name="$thumb_2_joint" type="revolute">
		<parent link="$thumb_1_link"/>
		<child link="$thumb_2_link"/>
		<dynamics damping="1.0" friction="0.0001"/>
		<origin rpy="0.00000 -0.00000 0.00000" xyz="0.00000 0.00000 0.01650"/>
		<axis xyz="0.00000 1.00000 0.00000"/>
		<limit effort="100" lower="-1.570796327" upper="1.570796327" velocity="5"/>
	</joint>
	<joint name="$thumb_3_joint" type="revolute">
		<parent link="$thumb_2_link"/>
		<child link="$thumb_3_link"/>
		<dynamics damping="1.0" friction="0.0001"/>
		<origin rpy="0.00000 -0.00000 0.00000" xyz="0.00000 0.00000 0.08650"/>
		<axis xyz="0.00000 1.00000 0.00000"/>
		<limit effort="100" lower="-1.570796327" upper="1.570796327" velocity="5"/>
	</joint>
</robot>
