<?xml version="1.0" ?>
<!-- =================================================================================== -->
<!-- |    This document was autogenerated by xacro from urdf/ur10_robot.urdf.xacro     | -->
<!-- |    EDITING THIS FILE BY HAND IS NOT RECOMMENDED                                 | -->
<!-- =================================================================================== -->
<robot name="ur10" xmlns:xacro="http://www.ros.org/wiki/xacro">
  <!-- common stuff -->
  <gazebo>
    <plugin filename="libgazebo_ros_control.so" name="ros_control">
      <!--robotNamespace>/</robotNamespace-->
      <!--robotSimType>gazebo_ros_control/DefaultRobotHWSim</robotSimType-->
    </plugin>
    <!--
    <plugin name="gazebo_ros_power_monitor_controller" filename="libgazebo_ros_power_monitor.so">
      <alwaysOn>true</alwaysOn>
      <updateRate>1.0</updateRate>
      <timeout>5</timeout>
      <powerStateTopic>power_state</powerStateTopic>
      <powerStateRate>10.0</powerStateRate>
      <fullChargeCapacity>87.78</fullChargeCapacity>     
      <dischargeRate>-474</dischargeRate>
      <chargeRate>525</chargeRate>
      <dischargeVoltage>15.52</dischargeVoltage>
      <chargeVoltage>16.41</chargeVoltage>
    </plugin>
-->
  </gazebo>
  <!-- ur10 -->
  <!-- arm -->
  <link name="base_link">
    <visual>
      <geometry>
        <mesh filename="package://UR/ur_description/meshes/ur10/visual/Base.dae"/>
      </geometry>
    </visual>
    <collision>
      <geometry>
        <mesh filename="package://UR/ur_description/meshes/ur10/collision/Base.dae"/>
      </geometry>
    </collision>
    <inertial>
      <mass value="4.0"/>
      <origin rpy="0 0 0" xyz="0.0 0.0 0.0"/>
      <inertia ixx="0.0061063308908" ixy="0.0" ixz="0.0" iyy="0.0061063308908" iyz="0.0" izz="0.01125"/>
    </inertial>
  </link>
  <joint name="shoulder_pan_joint" type="revolute">
    <parent link="base_link"/>
    <child link="shoulder_link"/>
    <origin rpy="0.0 0.0 0.0" xyz="0.0 0.0 0.1273"/>
    <axis xyz="0 0 1"/>
    <limit effort="330.0" lower="-6.2831853" upper="6.2831853" velocity="2.16"/>
    <dynamics damping="0.0" friction="0.0"/>
  </joint>
  <link name="shoulder_link">
    <visual>
      <geometry>
        <mesh filename="package://UR/ur_description/meshes/ur10/visual/Shoulder.dae"/>
      </geometry>
    </visual>
    <collision>
      <geometry>
        <mesh filename="package://UR/ur_description/meshes/ur10/collision/Shoulder.dae"/>
      </geometry>
    </collision>
    <inertial>
      <mass value="7.778"/>
      <origin rpy="0 0 0" xyz="0.0 0.0 0.0"/>
      <inertia ixx="0.0314743125769" ixy="0.0" ixz="0.0" iyy="0.0314743125769" iyz="0.0" izz="0.021875625"/>
    </inertial>
  </link>
  <joint name="shoulder_lift_joint" type="revolute">
    <parent link="shoulder_link"/>
    <child link="upper_arm_link"/>
    <origin rpy="0.0 1.570796325 0.0" xyz="0.0 0.220941 0.0"/>
    <axis xyz="0 1 0"/>
    <limit effort="330.0" lower="-6.2831853" upper="6.2831853" velocity="2.16"/>
    <dynamics damping="0.0" friction="0.0"/>
  </joint>
  <link name="upper_arm_link">
    <visual>
      <geometry>
        <mesh filename="package://UR/ur_description/meshes/ur10/visual/UpperArm.dae"/>
      </geometry>
    </visual>
    <collision>
      <geometry>
        <mesh filename="package://UR/ur_description/meshes/ur10/collision/UpperArm.dae"/>
      </geometry>
    </collision>
    <inertial>
      <mass value="12.93"/>
      <origin rpy="0 0 0" xyz="0.0 0.0 0.306"/>
      <inertia ixx="0.421753803798" ixy="0.0" ixz="0.0" iyy="0.421753803798" iyz="0.0" izz="0.036365625"/>
    </inertial>
  </link>
  <joint name="elbow_joint" type="revolute">
    <parent link="upper_arm_link"/>
    <child link="forearm_link"/>
    <origin rpy="0.0 0.0 0.0" xyz="0.0 -0.1719 0.612"/>
    <axis xyz="0 1 0"/>
    <limit effort="150.0" lower="-6.2831853" upper="6.2831853" velocity="3.15"/>
    <dynamics damping="0.0" friction="0.0"/>
  </joint>
  <link name="forearm_link">
    <visual>
      <geometry>
        <mesh filename="package://UR/ur_description/meshes/ur10/visual/Forearm.dae"/>
      </geometry>
    </visual>
    <collision>
      <geometry>
        <mesh filename="package://UR/ur_description/meshes/ur10/collision/Forearm.dae"/>
      </geometry>
    </collision>
    <inertial>
      <mass value="3.87"/>
      <origin rpy="0 0 0" xyz="0.0 0.0 0.28615"/>
      <inertia ixx="0.111069694097" ixy="0.0" ixz="0.0" iyy="0.111069694097" iyz="0.0" izz="0.010884375"/>
    </inertial>
  </link>
  <joint name="wrist_1_joint" type="revolute">
    <parent link="forearm_link"/>
    <child link="wrist_1_link"/>
    <origin rpy="0.0 1.570796325 0.0" xyz="0.0 0.0 0.5723"/>
    <axis xyz="0 1 0"/>
    <limit effort="54.0" lower="-6.2831853" upper="6.2831853" velocity="3.2"/>
    <dynamics damping="0.0" friction="0.0"/>
  </joint>
  <link name="wrist_1_link">
    <visual>
      <geometry>
        <mesh filename="package://UR/ur_description/meshes/ur10/visual/Wrist1.dae"/>
      </geometry>
    </visual>
    <collision>
      <geometry>
        <mesh filename="package://UR/ur_description/meshes/ur10/collision/Wrist1.dae"/>
      </geometry>
    </collision>
    <inertial>
      <mass value="1.96"/>
      <origin rpy="0 0 0" xyz="0.0 0.0 0.0"/>
      <inertia ixx="0.0051082479567" ixy="0.0" ixz="0.0" iyy="0.0051082479567" iyz="0.0" izz="0.0055125"/>
    </inertial>
  </link>
  <joint name="wrist_2_joint" type="revolute">
    <parent link="wrist_1_link"/>
    <child link="wrist_2_link"/>
    <origin rpy="0.0 0.0 0.0" xyz="0.0 0.1149 0.0"/>
    <axis xyz="0 0 1"/>
    <limit effort="54.0" lower="-6.2831853" upper="6.2831853" velocity="3.2"/>
    <dynamics damping="0.0" friction="0.0"/>
  </joint>
  <link name="wrist_2_link">
    <visual>
      <geometry>
        <mesh filename="package://UR/ur_description/meshes/ur10/visual/Wrist2.dae"/>
      </geometry>
    </visual>
    <collision>
      <geometry>
        <mesh filename="package://UR/ur_description/meshes/ur10/collision/Wrist2.dae"/>
      </geometry>
    </collision>
    <inertial>
      <mass value="1.96"/>
      <origin rpy="0 0 0" xyz="0.0 0.0 0.0"/>
      <inertia ixx="0.0051082479567" ixy="0.0" ixz="0.0" iyy="0.0051082479567" iyz="0.0" izz="0.0055125"/>
    </inertial>
  </link>
  <joint name="wrist_3_joint" type="revolute">
    <parent link="wrist_2_link"/>
    <child link="wrist_3_link"/>
    <origin rpy="0.0 0.0 0.0" xyz="0.0 0.0 0.1157"/>
    <axis xyz="0 1 0"/>
    <limit effort="54.0" lower="-6.2831853" upper="6.2831853" velocity="3.2"/>
    <dynamics damping="0.0" friction="0.0"/>
  </joint>
  <link name="wrist_3_link">
    <visual>
      <geometry>
        <mesh filename="package://UR/ur_description/meshes/ur10/visual/Wrist3.dae"/>
      </geometry>
    </visual>
    <collision>
      <geometry>
        <mesh filename="package://UR/ur_description/meshes/ur10/collision/Wrist3.dae"/>
      </geometry>
    </collision>
    <inertial>
      <mass value="0.202"/>
      <origin rpy="0 0 0" xyz="0.0 0.0 0.0"/>
      <inertia ixx="0.000526462289415" ixy="0.0" ixz="0.0" iyy="0.000526462289415" iyz="0.0" izz="0.000568125"/>
    </inertial>
  </link>
  <joint name="ee_fixed_joint" type="fixed">
    <parent link="wrist_3_link"/>
    <child link="ee_link"/>
    <origin rpy="0.0 0.0 1.570796325" xyz="0.0 0.0922 0.0"/>
  </joint>
  <link name="ee_link"/>
  <transmission name="shoulder_pan_trans">
    <type>transmission_interface/SimpleTransmission</type>
    <joint name="shoulder_pan_joint"/>
    <actuator name="shoulder_pan_motor">
      <hardwareInterface>EffortJointInterface</hardwareInterface>
      <mechanicalReduction>1</mechanicalReduction>
    </actuator>
  </transmission>
  <transmission name="shoulder_lift_trans">
    <type>transmission_interface/SimpleTransmission</type>
    <joint name="shoulder_lift_joint"/>
    <actuator name="shoulder_lift_motor">
      <hardwareInterface>EffortJointInterface</hardwareInterface>
      <mechanicalReduction>1</mechanicalReduction>
    </actuator>
  </transmission>
  <transmission name="elbow_trans">
    <type>transmission_interface/SimpleTransmission</type>
    <joint name="elbow_joint"/>
    <actuator name="elbow_motor">
      <hardwareInterface>EffortJointInterface</hardwareInterface>
      <mechanicalReduction>1</mechanicalReduction>
    </actuator>
  </transmission>
  <transmission name="wrist_1_trans">
    <type>transmission_interface/SimpleTransmission</type>
    <joint name="wrist_1_joint"/>
    <actuator name="wrist_1_motor">
      <hardwareInterface>EffortJointInterface</hardwareInterface>
      <mechanicalReduction>1</mechanicalReduction>
    </actuator>
  </transmission>
  <transmission name="wrist_2_trans">
    <type>transmission_interface/SimpleTransmission</type>
    <joint name="wrist_2_joint"/>
    <actuator name="wrist_2_motor">
      <hardwareInterface>EffortJointInterface</hardwareInterface>
      <mechanicalReduction>1</mechanicalReduction>
    </actuator>
  </transmission>
  <transmission name="wrist_3_trans">
    <type>transmission_interface/SimpleTransmission</type>
    <joint name="wrist_3_joint"/>
    <actuator name="wrist_3_motor">
      <hardwareInterface>EffortJointInterface</hardwareInterface>
      <mechanicalReduction>1</mechanicalReduction>
    </actuator>
  </transmission>
  <link name="world"/>
  <joint name="world_joint" type="fixed">
    <parent link="world"/>
    <child link="base_link"/>
    <origin rpy="0.0 0.0 0.0" xyz="0.0 0.0 0.0"/>
  </joint>


  <link name="$palm_link">
    <inertial>
      <mass value="1.0288" /><!-- density 1652.3 kg/m3 adjusted to have final total mass of 1.95 -->
      <origin xyz="0 0 0.0386" />
      <inertia ixx="0.0011896" ixy="0.0" ixz="0.0" iyy="0.0011889" iyz="0.0" izz="0.0015636" />
    </inertial>
    <visual>
      <origin xyz="0 0 0" rpy="0 0 0" />
      <geometry>
        <mesh filename="grippers/threeFingers/sdh/palm.stl" />
      </geometry>
      <material name="Schunk/DarkGrey">
        <color rgba="1 0.84 0 1"/>
      </material>
    </visual>
    <collision>
      <origin xyz="0 0 0" rpy="0 0 0" />
      <geometry>
        <mesh filename="grippers/threeFingers/sdh/palm_collision.stl"/>
      </geometry>
    </collision>
  </link>

  <joint name="ee_fixed_joint2" type="fixed">
    <parent link="ee_link"/>
    <child link="$palm_link"/>
    <origin rpy="0.0 1.57 0.0" xyz="0.0 0.0 0.0"/>
  </joint>
  <!-- grasp link -->
  <!-- <joint name="$grasp_joint" type="fixed" >
    <origin xyz="0 0 0.15" rpy="0 0 0"/>
    <parent link="$palm_link" />
    <child link="$grasp_link" />
  </joint>

  <link name="$grasp_link" />
 -->
  <!-- tip link -->
  <!-- <joint name="$tip_joint" type="fixed" >
    <origin xyz="0 0 0.22" rpy="0 0 0"/>
    <parent link="$palm_link" />
    <child link="$tip_link" />
  </joint>

  <link name="$tip_link" />
 -->
  <!-- finger1 -->
  <!-- joint between sdh_palm_link and sdh_finger_11_link -->
  <joint name="$knuckle_joint" type="revolute">
    <origin xyz="0.01905 0.033 0.0745" rpy="0 0 3.14159265" />
    <parent link="$palm_link"/>
    <child link="$finger_11_link"/>
    <axis xyz="0 0 1" />
    <dynamics damping="1" />
    <limit effort="100" lower="0" upper="1.570796327" velocity="5"/>
  </joint>

  <link name="$finger_11_link">
    <inertial>
      <mass value="0.047" /> <!-- density of aluminum -->
      <origin xyz="0.0 2.2105e-03 1.2155e-02" />
      <inertia ixx="1.5889e-05" ixy="0.0" ixz="0.0" iyy="6.9350e-06" iyz="-4.7500e-07" izz="1.4915e-05" />
    </inertial>
    <visual>
      <origin xyz="0 0 0" rpy="0 0 0" />
      <geometry>
        <mesh filename="grippers/threeFingers/sdh/knuckle.stl" />
      </geometry>
      <material name="Schunk/DarkGrey">
        <color rgba="1 0.84 0 1.0"/>
      </material>
    </visual>
    <collision>
      <origin xyz="0 0 0" rpy="0 0 0" />
      <geometry>
      <mesh filename="grippers/threeFingers/sdh/knuckle_collision.stl"/>
      </geometry>
    </collision>
  </link>

  <!-- joint between sdh_finger_11_link and sdh_finger_12_link -->
  <joint name="$finger_12_joint" type="revolute">
    <origin xyz="0 0 0.0165" rpy="0 0 0" />
    <parent link="$finger_11_link"/>
    <child link="$finger_12_link"/>
    <axis xyz="0 1 0" />
    <dynamics damping="1" />
    <limit effort="100" lower="-1.570796327" upper="1.570796327" velocity="5"/>
  </joint>

  <link name="$finger_12_link">
    <inertial>
      <mass value="0.167" /> <!-- density of aluminum -->
      <origin xyz="0.0007467 -0.0000378 0.0430192" />
      <inertia ixx="1.5920e-04" ixy="0.0" ixz="-2.3750e-08" iyy="1.5903e-04" iyz="9.3100e-06" izz="1.9142e-05" />
    </inertial>
    <visual>
      <origin xyz="0 0 0" rpy="0 0 0" />
      <geometry>
        <mesh filename="grippers/threeFingers/sdh/finger.stl" />
      </geometry>
      <material name="Schunk/LightGrey">
        <color rgba="1 0.84 0 1.0"/>
      </material>
    </visual>
    <collision>
      <origin xyz="0 0 0" rpy="0 0 0" />
      <geometry>
        <mesh filename="grippers/threeFingers/sdh/finger.stl"/>
      </geometry>
    </collision>
  </link>

  <!-- joint between sdh_finger_12_link and sdh_finger_13_link -->
  <joint name="$finger_13_joint" type="revolute">

    <origin xyz="0 0 0.0865" rpy="0 0 0" />
    <parent link="$finger_12_link"/>
    <child link="$finger_13_link"/>
    <axis xyz="0 1 0" />
    <dynamics damping="1" />
    <limit effort="100" lower="-1.570796327" upper="1.570796327" velocity="5"/>
  </joint>

  <link name="$finger_13_link">
    <inertial>
      <mass value="0.0929" /> <!-- density of aluminum -->
      <origin xyz="0.0007467 -0.0000378 0.0430192" />
      <inertia ixx="4.2323e-05" ixy="1.9000e-07" ixz="-5.2250e-07" iyy="3.9734e-05" iyz="5.7950e-06" izz="1.1210e-05" />
    </inertial>
    <visual>
      <origin xyz="0 0 0" rpy="0 0 0" />
      <geometry>
        <mesh filename="grippers/threeFingers/sdh/finger_tip.stl" />
      </geometry>
      <material name="Schunk/LightGrey">
        <color rgba="1 0.84 0 1.0"/>
      </material>
    </visual>
    <collision>
      <origin xyz="0 0 0" rpy="0 0 0" />
      <geometry>
        <mesh filename="grippers/threeFingers/sdh/finger_tip.stl"/>
      </geometry>
    </collision>
  </link>

  <!-- finger2 -->
  <!-- joint between sdh_palm_link and sdh_finger_21_link -->
  <joint name="$finger_21_joint" type="revolute">
    <mimic joint="$knuckle_joint" multiplier="1" offset="0"/>
    <origin xyz="0.01905 -0.033 0.0745" rpy="0 0 3.14159265" />
    <parent link="$palm_link"/>
    <child link="$finger_21_link"/>
    <axis xyz="0 0 -1" />
    <dynamics damping="1" />
    <limit effort="100" lower="0" upper="1.570796327" velocity="5"/>
  </joint>

  <link name="$finger_21_link">
    <inertial>
      <mass value="0.047" /> <!-- density of aluminum -->
      <origin xyz="0.0 2.2105e-03 1.2155e-02" />
      <inertia ixx="1.5889e-05" ixy="0.0" ixz="0.0" iyy="6.9350e-06" iyz="-4.7500e-07" izz="1.4915e-05" />
    </inertial>
    <visual>
      <origin xyz="0 0 0" rpy="0 0 0" />
      <geometry>
        <mesh filename="grippers/threeFingers/sdh/knuckle.stl" />
      </geometry>
      <material name="Schunk/DarkGrey">
        <color rgba="1 0.84 0 1.0"/>
      </material>
    </visual>
    <collision>
      <origin xyz="0 0 0" rpy="0 0 0" />
      <geometry>
        <mesh filename="grippers/threeFingers/sdh/knuckle_collision.stl"/>
      </geometry>
    </collision>
  </link>

  <!-- joint between sdh_finger_21_link and sdh_finger_22_link -->
  <joint name="$finger_22_joint" type="revolute">
    <origin xyz="0 0 0.0165" rpy="0 0 0" />
    <parent link="$finger_21_link"/>
    <child link="$finger_22_link"/>
    <axis xyz="0 1 0" />
    <dynamics damping="1" />
    <limit effort="100" lower="-1.570796327" upper="1.570796327" velocity="5"/>
  </joint>

  <link name="$finger_22_link">
    <inertial>
      <mass value="0.167" /> <!-- density of aluminum -->
      <origin xyz="0.0007467 -0.0000378 0.0430192" />
      <inertia ixx="1.5920e-04" ixy="0.0" ixz="-2.3750e-08" iyy="1.5903e-04" iyz="9.3100e-06" izz="1.9142e-05" />
    </inertial>
    <visual>
      <origin xyz="0 0 0" rpy="0 0 0" />
      <geometry>
        <mesh filename="grippers/threeFingers/sdh/finger.stl" />
      </geometry>
      <material name="Schunk/LightGrey">
        <color rgba="1 0.84 0 1.0"/>
      </material>
    </visual>
    <collision>
      <origin xyz="0 0 0" rpy="0 0 0" />
      <geometry>
        <mesh filename="grippers/threeFingers/sdh/finger.stl"/>
      </geometry>
    </collision>
  </link>

  <!-- joint between sdh_finger_22_link and sdh_finger_23_link -->
  <joint name="$finger_23_joint" type="revolute">
    <origin xyz="0 0 0.0865" rpy="0 0 0" />
    <parent link="$finger_22_link"/>
    <child link="$finger_23_link"/>
    <axis xyz="0 1 0" />
    <dynamics damping="1" />
    <limit effort="100" lower="-1.570796327" upper="1.570796327" velocity="5"/>
  </joint>

  <link name="$finger_23_link">
    <inertial>
      <mass value="0.0929" /> <!-- density of aluminum -->
      <origin xyz="0.0007467 -0.0000378 0.0430192" />
      <inertia ixx="4.2323e-05" ixy="1.9000e-07" ixz="-5.2250e-07" iyy="3.9734e-05" iyz="5.7950e-06" izz="1.1210e-05" />
    </inertial>
    <visual>
      <origin xyz="0 0 0" rpy="0 0 0" />
      <geometry>
        <mesh filename="grippers/threeFingers/sdh/finger_tip.stl" />
      </geometry>
      <material name="Schunk/LightGrey">
        <color rgba="1 0.84 0 1.0"/>
      </material>
    </visual>
    <collision>
      <origin xyz="0 0 0" rpy="0 0 0" />
      <geometry>
        <mesh filename="grippers/threeFingers/sdh/finger_tip.stl"/>
      </geometry>
    </collision>
  </link>

  <!-- thumb -->
  <!-- joint between sdh_palm_link and sdh_thumb_1_link -->
  <joint name="$thumb_1_joint" type="fixed">
    <origin xyz="-0.03811 0 0.0745 " rpy="0 0 0" />
    <parent link="$palm_link"/>
    <child link="$thumb_1_link"/>
  </joint>

  <link name="$thumb_1_link">
    <inertial>
      <mass value="0.047" /> <!-- density of aluminum -->
      <origin xyz="0.0 2.2105e-03 1.2155e-02" />
      <inertia ixx="1.5889e-05" ixy="0.0" ixz="0.0" iyy="6.9350e-06" iyz="-4.7500e-07" izz="1.4915e-05" />
    </inertial>
    <visual>
      <origin xyz="0 0 0" rpy="0 0 0" />
      <geometry>
        <mesh filename="grippers/threeFingers/sdh/knuckle.stl" />
      </geometry>
      <material name="Schunk/DarkGrey">
        <color rgba="1 0.84 0 1.0"/>
      </material>
    </visual>
    <collision>
      <origin xyz="0 0 0" rpy="0 0 0" />
      <geometry>
        <mesh filename="grippers/threeFingers/sdh/knuckle_collision.stl"/>
      </geometry>
    </collision>
  </link>

  <!-- joint between sdh_thumb_1_link and shd_thumb_2_link -->
  <joint name="$thumb_2_joint" type="revolute">
  <origin xyz="0 0 0.0165" rpy="0 0 0" />
  <parent link="$thumb_1_link"/>
  <child link="$thumb_2_link"/>
  <axis xyz="0 1 0" />
  <dynamics damping="1" />
  <limit effort="100" lower="-1.570796327" upper="1.570796327" velocity="5"/>
  </joint>

  <link name="$thumb_2_link">
    <inertial>
      <mass value="0.167" /> <!-- density of aluminum -->
      <origin xyz="0.0007467 -0.0000378 0.0430192" />
      <inertia ixx="1.5920e-04" ixy="0.0" ixz="-2.3750e-08" iyy="1.5903e-04" iyz="9.3100e-06" izz="1.9142e-05" />
    </inertial>
    <visual>
      <origin xyz="0 0 0" rpy="0 0 0" />
      <geometry>
        <mesh filename="grippers/threeFingers/sdh/finger.stl" />
      </geometry>
      <material name="Schunk/LightGrey">
        <color rgba="1 0.84 0 1.0"/>
      </material>
    </visual>
    <collision>
      <origin xyz="0 0 0" rpy="0 0 0" />
      <geometry>
        <mesh filename="grippers/threeFingers/sdh/finger.stl"/>
      </geometry>
    </collision>
  </link>

  <!-- joint between sdh_thumb_2_link and sdh_thumb_3_link -->
  <joint name="$thumb_3_joint" type="revolute">
    <origin xyz="0 0 0.0865" rpy="0 0 0" />
    <parent link="$thumb_2_link"/>
    <child link="$thumb_3_link"/>
    <axis xyz="0 1 0" />
    <dynamics damping="1" />
    <limit effort="100" lower="-1.570796327" upper="1.570796327" velocity="5"/>
  </joint>

  <link name="$thumb_3_link">
    <inertial>
      <mass value="0.0929" /> <!-- density of aluminum -->
      <origin xyz="0.0007467 -0.0000378 0.0430192" />
      <inertia ixx="4.2323e-05" ixy="1.9000e-07" ixz="-5.2250e-07" iyy="3.9734e-05" iyz="5.7950e-06" izz="1.1210e-05" />
    </inertial>
    <visual>
      <origin xyz="0 0 0" rpy="0 0 0" />
      <geometry>
        <mesh filename="grippers/threeFingers/sdh/finger_tip.stl" />
      </geometry>
      <material name="Schunk/LightGrey">
        <color rgba="1 0.84 0 1.0"/>
      </material>
    </visual>
    <collision>
      <origin xyz="0 0 0" rpy="0 0 0" />
      <geometry>
        <mesh filename="grippers/threeFingers/sdh/finger_tip.stl"/>
      </geometry>
    </collision>
  </link>
</robot>